Workbook

Sheet The Plan
B2: THE PLAN | G2: Updated Apr 30, 2026
B3: Hubele family debt-free roadmap
A5: =("$"&TEXT('Debt Tracker'!E30-'Debt Tracker'!L30,"#,##0")&" of $"&TEXT('Debt Tracker'!E30,"#,##0")&" paid off") -> $6,379 of $85,142 paid off | C5: =VLOOKUP($C$15,$I$100:$K$103,2,FALSE()) -> 15 | E5: =DATE(2026,5+VLOOKUP($C$15,$I$100:$K$103,2,FALSE())-1,1) -> 46569 | G5: =IF(('Debt Tracker'!E30-'Debt Tracker'!L30)/'Debt Tracker'!E30=0,"🚦 NOT STARTED",IF(('Debt Tracker'!E30-'Debt Tracker'!L30)/'Debt Tracker'!E30>=1,"🎉 DEBT FREE!","✓ IN PROGRESS")) -> ✓ IN PROGRESS
A6: =REPT("█",ROUND(50*(('Debt Tracker'!E30-'Debt Tracker'!L30)/'Debt Tracker'!E30),0))&REPT("░",50-ROUND(50*(('Debt Tracker'!E30-'Debt Tracker'!L30)/'Debt Tracker'!E30),0)) -> ████░░░░░░░░░░░░░░░░░░░░░░░░░░░░░░░░░░░░░░░░░░░░░░ | G6: =("("&TEXT(('Debt Tracker'!E30-'Debt Tracker'!L30)/'Debt Tracker'!E30,"0.0%")&" complete)") -> (7.5% complete)
A7: NEXT UP | B7: 1️⃣ THIS MONTH | D7: 2️⃣ NEXT | F7: 3️⃣ AFTER
B8: =VLOOKUP($C$15,$I$100:$T$103,4,FALSE()) -> Mattress Firm / Synchrony Home | D8: =VLOOKUP($C$15,$I$100:$T$103,5,FALSE()) -> Ashley Furniture / Synchrony | F8: =VLOOKUP($C$15,$I$100:$T$103,6,FALSE()) -> Best Buy / Citi
A9: 💰 Cash on Hand: | B9: =Payments!E2 -> 3408.09 | C9: 📈 Income (CSV): | D9: =SUMIFS(Payments!F:F,Payments!D:D,"Income") -> 12540.19 | E9: 📉 Expenses (CSV): | F9: =SUMIFS(Payments!F:F,Payments!D:D,"Expense") -> 13224.39 | G9: 💵 Net: | H9: =D9-F9 -> -684.2
B10: 💡 DO THIS NOW
B11: =VLOOKUP($C$15,$I$100:$T$103,10,FALSE()) -> Pay $1,583 → Mattress Firm / Synchrony Home AND $934 → Ashley Furniture / Synchrony
B12: =VLOOKUP($C$15,$I$100:$T$103,11,FALSE()) -> You have $3,472/mo extra. Kills BOTH this month — over $2,517 of debt gone.
B14: 🔧 PLAY WITH YOUR PLAN
B15: Pick a scenario: | C15: Current Plan | E15: 👆 changes the numbers above
B16: JUST MINIMUMS | C16: CONSERVATIVE | D16: CURRENT | E16: AGGRESSIVE | F16: WHAT IT MEANS
B17: $0 extra | C17: +$1,500/mo | D17: +$3,472/mo | E17: +$3,472 +$20K | F17: • Minimums = 3.5 yrs of paying interest, no progress • Conservative = realistic if cash gets tight • Current = your full $3,472/mo budget surplus • Aggressive = use $20K savings to wipe out 8 highest-APR debts day 1
B18: 37 mo | C18: 22 mo | D18: 15 mo | E18: 11 mo
B19: May 2029 | C19: Feb 2028 | D19: Jul 2027 | E19: Mar 2027
B20: $34,132 interest | C20: $18,273 interest | D20: $11,780 interest | E20: $6,046 interest
B21: +22mo, +$22,352 | C21: +7mo, +$6,492 | D21: (your active) | E21: -4mo, −$5,735
B22: 🗓️ FULL PAYOFF SCHEDULE — DEBTS DIE IN THIS ORDER
B23: # | C23: Debt | D23: When | E23: Balance Today | F23: Pay This Much | G23: What Happens After
B24: =IFERROR(INDEX($U$200:$AR$224,1,VLOOKUP($C$15,$I$100:$T$103,12,FALSE())+1),"") -> 1 | C24: =IFERROR(INDEX($U$200:$AR$224,1,VLOOKUP($C$15,$I$100:$T$103,12,FALSE())+2),"") -> Mattress Firm / Synchrony Home | D24: =IFERROR(INDEX($U$200:$AR$224,1,VLOOKUP($C$15,$I$100:$T$103,12,FALSE())+3),"") -> 46143 | E24: =IFERROR(INDEX($U$200:$AR$224,1,VLOOKUP($C$15,$I$100:$T$103,12,FALSE())+4),"") -> 1583.49 | F24: =IFERROR(INDEX($U$200:$AR$224,1,VLOOKUP($C$15,$I$100:$T$103,12,FALSE())+5),"") -> 1712.49 | G24: =IFERROR(INDEX($U$200:$AR$224,1,VLOOKUP($C$15,$I$100:$T$103,12,FALSE())+6),"") -> First win! Frees up $129/mo.
B25: =IFERROR(INDEX($U$200:$AR$224,2,VLOOKUP($C$15,$I$100:$T$103,12,FALSE())+1),"") -> 2 | C25: =IFERROR(INDEX($U$200:$AR$224,2,VLOOKUP($C$15,$I$100:$T$103,12,FALSE())+2),"") -> Ashley Furniture / Synchrony | D25: =IFERROR(INDEX($U$200:$AR$224,2,VLOOKUP($C$15,$I$100:$T$103,12,FALSE())+3),"") -> 46143 | E25: =IFERROR(INDEX($U$200:$AR$224,2,VLOOKUP($C$15,$I$100:$T$103,12,FALSE())+4),"") -> 933.82 | F25: =IFERROR(INDEX($U$200:$AR$224,2,VLOOKUP($C$15,$I$100:$T$103,12,FALSE())+5),"") -> 966.82 | G25: =IFERROR(INDEX($U$200:$AR$224,2,VLOOKUP($C$15,$I$100:$T$103,12,FALSE())+6),"") -> Same-month kill! +$33/mo.
B26: =IFERROR(INDEX($U$200:$AR$224,3,VLOOKUP($C$15,$I$100:$T$103,12,FALSE())+1),"") -> 3 | C26: =IFERROR(INDEX($U$200:$AR$224,3,VLOOKUP($C$15,$I$100:$T$103,12,FALSE())+2),"") -> Best Buy / Citi | D26: =IFERROR(INDEX($U$200:$AR$224,3,VLOOKUP($C$15,$I$100:$T$103,12,FALSE())+3),"") -> 46174 | E26: =IFERROR(INDEX($U$200:$AR$224,3,VLOOKUP($C$15,$I$100:$T$103,12,FALSE())+4),"") -> 1200 | F26: =IFERROR(INDEX($U$200:$AR$224,3,VLOOKUP($C$15,$I$100:$T$103,12,FALSE())+5),"") -> 1229 | G26: =IFERROR(INDEX($U$200:$AR$224,3,VLOOKUP($C$15,$I$100:$T$103,12,FALSE())+6),"") -> +$29/mo to next attack.
B27: =IFERROR(INDEX($U$200:$AR$224,4,VLOOKUP($C$15,$I$100:$T$103,12,FALSE())+1),"") -> 4 | C27: =IFERROR(INDEX($U$200:$AR$224,4,VLOOKUP($C$15,$I$100:$T$103,12,FALSE())+2),"") -> Capital One Platinum | D27: =IFERROR(INDEX($U$200:$AR$224,4,VLOOKUP($C$15,$I$100:$T$103,12,FALSE())+3),"") -> 46204 | E27: =IFERROR(INDEX($U$200:$AR$224,4,VLOOKUP($C$15,$I$100:$T$103,12,FALSE())+4),"") -> 5930.94 | F27: =IFERROR(INDEX($U$200:$AR$224,4,VLOOKUP($C$15,$I$100:$T$103,12,FALSE())+5),"") -> 6130.94 | G27: =IFERROR(INDEX($U$200:$AR$224,4,VLOOKUP($C$15,$I$100:$T$103,12,FALSE())+6),"") -> Big payoff — $200/mo joins war chest.
B28: =IFERROR(INDEX($U$200:$AR$224,5,VLOOKUP($C$15,$I$100:$T$103,12,FALSE())+1),"") -> 5 | C28: =IFERROR(INDEX($U$200:$AR$224,5,VLOOKUP($C$15,$I$100:$T$103,12,FALSE())+2),"") -> Amex Delta SkyMiles Gold | D28: =IFERROR(INDEX($U$200:$AR$224,5,VLOOKUP($C$15,$I$100:$T$103,12,FALSE())+3),"") -> 46266 | E28: =IFERROR(INDEX($U$200:$AR$224,5,VLOOKUP($C$15,$I$100:$T$103,12,FALSE())+4),"") -> 7294.06 | F28: =IFERROR(INDEX($U$200:$AR$224,5,VLOOKUP($C$15,$I$100:$T$103,12,FALSE())+5),"") -> 7499.93 | G28: =IFERROR(INDEX($U$200:$AR$224,5,VLOOKUP($C$15,$I$100:$T$103,12,FALSE())+6),"") -> Big payoff — $206/mo joins war chest.
B29: =IFERROR(INDEX($U$200:$AR$224,6,VLOOKUP($C$15,$I$100:$T$103,12,FALSE())+1),"") -> 6 | C29: =IFERROR(INDEX($U$200:$AR$224,6,VLOOKUP($C$15,$I$100:$T$103,12,FALSE())+2),"") -> Menards Big Card (Cap One) | D29: =IFERROR(INDEX($U$200:$AR$224,6,VLOOKUP($C$15,$I$100:$T$103,12,FALSE())+3),"") -> 46296 | E29: =IFERROR(INDEX($U$200:$AR$224,6,VLOOKUP($C$15,$I$100:$T$103,12,FALSE())+4),"") -> 2758.32 | F29: =IFERROR(INDEX($U$200:$AR$224,6,VLOOKUP($C$15,$I$100:$T$103,12,FALSE())+5),"") -> 2850.32 | G29: =IFERROR(INDEX($U$200:$AR$224,6,VLOOKUP($C$15,$I$100:$T$103,12,FALSE())+6),"") -> +$92/mo to next attack.
B30: =IFERROR(INDEX($U$200:$AR$224,7,VLOOKUP($C$15,$I$100:$T$103,12,FALSE())+1),"") -> 7 | C30: =IFERROR(INDEX($U$200:$AR$224,7,VLOOKUP($C$15,$I$100:$T$103,12,FALSE())+2),"") -> Amex Platinum (Pay Over Time) | D30: =IFERROR(INDEX($U$200:$AR$224,7,VLOOKUP($C$15,$I$100:$T$103,12,FALSE())+3),"") -> 46296 | E30: =IFERROR(INDEX($U$200:$AR$224,7,VLOOKUP($C$15,$I$100:$T$103,12,FALSE())+4),"") -> 1406.09 | F30: =IFERROR(INDEX($U$200:$AR$224,7,VLOOKUP($C$15,$I$100:$T$103,12,FALSE())+5),"") -> 1446.09 | G30: =IFERROR(INDEX($U$200:$AR$224,7,VLOOKUP($C$15,$I$100:$T$103,12,FALSE())+6),"") -> Same-month kill! +$40/mo.
B31: =IFERROR(INDEX($U$200:$AR$224,8,VLOOKUP($C$15,$I$100:$T$103,12,FALSE())+1),"") -> 8 | C31: =IFERROR(INDEX($U$200:$AR$224,8,VLOOKUP($C$15,$I$100:$T$103,12,FALSE())+2),"") -> Affirm — Best Buy (Dec) | D31: =IFERROR(INDEX($U$200:$AR$224,8,VLOOKUP($C$15,$I$100:$T$103,12,FALSE())+3),"") -> 46327 | E31: =IFERROR(INDEX($U$200:$AR$224,8,VLOOKUP($C$15,$I$100:$T$103,12,FALSE())+4),"") -> 3020.12 | F31: =IFERROR(INDEX($U$200:$AR$224,8,VLOOKUP($C$15,$I$100:$T$103,12,FALSE())+5),"") -> 3171.13 | G31: =IFERROR(INDEX($U$200:$AR$224,8,VLOOKUP($C$15,$I$100:$T$103,12,FALSE())+6),"") -> +$151/mo to next attack.
B32: =IFERROR(INDEX($U$200:$AR$224,9,VLOOKUP($C$15,$I$100:$T$103,12,FALSE())+1),"") -> 9 | C32: =IFERROR(INDEX($U$200:$AR$224,9,VLOOKUP($C$15,$I$100:$T$103,12,FALSE())+2),"") -> Capital One Quicksilver | D32: =IFERROR(INDEX($U$200:$AR$224,9,VLOOKUP($C$15,$I$100:$T$103,12,FALSE())+3),"") -> 46327 | E32: =IFERROR(INDEX($U$200:$AR$224,9,VLOOKUP($C$15,$I$100:$T$103,12,FALSE())+4),"") -> 1169.64 | F32: =IFERROR(INDEX($U$200:$AR$224,9,VLOOKUP($C$15,$I$100:$T$103,12,FALSE())+5),"") -> 1207.64 | G32: =IFERROR(INDEX($U$200:$AR$224,9,VLOOKUP($C$15,$I$100:$T$103,12,FALSE())+6),"") -> Same-month kill! +$38/mo.
B33: =IFERROR(INDEX($U$200:$AR$224,10,VLOOKUP($C$15,$I$100:$T$103,12,FALSE())+1),"") -> 10 | C33: =IFERROR(INDEX($U$200:$AR$224,10,VLOOKUP($C$15,$I$100:$T$103,12,FALSE())+2),"") -> Affirm — Best Buy (Feb) | D33: =IFERROR(INDEX($U$200:$AR$224,10,VLOOKUP($C$15,$I$100:$T$103,12,FALSE())+3),"") -> 46327 | E33: =IFERROR(INDEX($U$200:$AR$224,10,VLOOKUP($C$15,$I$100:$T$103,12,FALSE())+4),"") -> 1160.62 | F33: =IFERROR(INDEX($U$200:$AR$224,10,VLOOKUP($C$15,$I$100:$T$103,12,FALSE())+5),"") -> 1233.16 | G33: =IFERROR(INDEX($U$200:$AR$224,10,VLOOKUP($C$15,$I$100:$T$103,12,FALSE())+6),"") -> Same-month kill! +$73/mo.
B34: =IFERROR(INDEX($U$200:$AR$224,11,VLOOKUP($C$15,$I$100:$T$103,12,FALSE())+1),"") -> 11 | C34: =IFERROR(INDEX($U$200:$AR$224,11,VLOOKUP($C$15,$I$100:$T$103,12,FALSE())+2),"") -> Affirm — Shady Rays | D34: =IFERROR(INDEX($U$200:$AR$224,11,VLOOKUP($C$15,$I$100:$T$103,12,FALSE())+3),"") -> 46327 | E34: =IFERROR(INDEX($U$200:$AR$224,11,VLOOKUP($C$15,$I$100:$T$103,12,FALSE())+4),"") -> 114.71 | F34: =IFERROR(INDEX($U$200:$AR$224,11,VLOOKUP($C$15,$I$100:$T$103,12,FALSE())+5),"") -> 133.82 | G34: =IFERROR(INDEX($U$200:$AR$224,11,VLOOKUP($C$15,$I$100:$T$103,12,FALSE())+6),"") -> Same-month kill! +$19/mo.
B35: =IFERROR(INDEX($U$200:$AR$224,12,VLOOKUP($C$15,$I$100:$T$103,12,FALSE())+1),"") -> 12 | C35: =IFERROR(INDEX($U$200:$AR$224,12,VLOOKUP($C$15,$I$100:$T$103,12,FALSE())+2),"") -> Discover | D35: =IFERROR(INDEX($U$200:$AR$224,12,VLOOKUP($C$15,$I$100:$T$103,12,FALSE())+3),"") -> 46357 | E35: =IFERROR(INDEX($U$200:$AR$224,12,VLOOKUP($C$15,$I$100:$T$103,12,FALSE())+4),"") -> 2758 | F35: =IFERROR(INDEX($U$200:$AR$224,12,VLOOKUP($C$15,$I$100:$T$103,12,FALSE())+5),"") -> 2838 | G35: =IFERROR(INDEX($U$200:$AR$224,12,VLOOKUP($C$15,$I$100:$T$103,12,FALSE())+6),"") -> +$80/mo to next attack.
B36: =IFERROR(INDEX($U$200:$AR$224,13,VLOOKUP($C$15,$I$100:$T$103,12,FALSE())+1),"") -> 13 | C36: =IFERROR(INDEX($U$200:$AR$224,13,VLOOKUP($C$15,$I$100:$T$103,12,FALSE())+2),"") -> Credit One Bank | D36: =IFERROR(INDEX($U$200:$AR$224,13,VLOOKUP($C$15,$I$100:$T$103,12,FALSE())+3),"") -> 46357 | E36: =IFERROR(INDEX($U$200:$AR$224,13,VLOOKUP($C$15,$I$100:$T$103,12,FALSE())+4),"") -> 300 | F36: =IFERROR(INDEX($U$200:$AR$224,13,VLOOKUP($C$15,$I$100:$T$103,12,FALSE())+5),"") -> 308.25 | G36: =IFERROR(INDEX($U$200:$AR$224,13,VLOOKUP($C$15,$I$100:$T$103,12,FALSE())+6),"") -> Same-month kill! +$8/mo.
B37: =IFERROR(INDEX($U$200:$AR$224,14,VLOOKUP($C$15,$I$100:$T$103,12,FALSE())+1),"") -> 14 | C37: =IFERROR(INDEX($U$200:$AR$224,14,VLOOKUP($C$15,$I$100:$T$103,12,FALSE())+2),"") -> PayPal Credit (Hannah) / Synchrony | D37: =IFERROR(INDEX($U$200:$AR$224,14,VLOOKUP($C$15,$I$100:$T$103,12,FALSE())+3),"") -> 46357 | E37: =IFERROR(INDEX($U$200:$AR$224,14,VLOOKUP($C$15,$I$100:$T$103,12,FALSE())+4),"") -> 3116.13 | F37: =IFERROR(INDEX($U$200:$AR$224,14,VLOOKUP($C$15,$I$100:$T$103,12,FALSE())+5),"") -> 3215.13 | G37: =IFERROR(INDEX($U$200:$AR$224,14,VLOOKUP($C$15,$I$100:$T$103,12,FALSE())+6),"") -> Same-month kill! +$99/mo.
B38: =IFERROR(INDEX($U$200:$AR$224,15,VLOOKUP($C$15,$I$100:$T$103,12,FALSE())+1),"") -> 15 | C38: =IFERROR(INDEX($U$200:$AR$224,15,VLOOKUP($C$15,$I$100:$T$103,12,FALSE())+2),"") -> PayPal Credit (Brad) / Synchrony | D38: =IFERROR(INDEX($U$200:$AR$224,15,VLOOKUP($C$15,$I$100:$T$103,12,FALSE())+3),"") -> 46388 | E38: =IFERROR(INDEX($U$200:$AR$224,15,VLOOKUP($C$15,$I$100:$T$103,12,FALSE())+4),"") -> 1570.31 | F38: =IFERROR(INDEX($U$200:$AR$224,15,VLOOKUP($C$15,$I$100:$T$103,12,FALSE())+5),"") -> 1614.31 | G38: =IFERROR(INDEX($U$200:$AR$224,15,VLOOKUP($C$15,$I$100:$T$103,12,FALSE())+6),"") -> +$44/mo to next attack.
B39: =IFERROR(INDEX($U$200:$AR$224,16,VLOOKUP($C$15,$I$100:$T$103,12,FALSE())+1),"") -> 16 | C39: =IFERROR(INDEX($U$200:$AR$224,16,VLOOKUP($C$15,$I$100:$T$103,12,FALSE())+2),"") -> Amex Blue Cash Preferred | D39: =IFERROR(INDEX($U$200:$AR$224,16,VLOOKUP($C$15,$I$100:$T$103,12,FALSE())+3),"") -> 46388 | E39: =IFERROR(INDEX($U$200:$AR$224,16,VLOOKUP($C$15,$I$100:$T$103,12,FALSE())+4),"") -> 1015.61 | F39: =IFERROR(INDEX($U$200:$AR$224,16,VLOOKUP($C$15,$I$100:$T$103,12,FALSE())+5),"") -> 1055.61 | G39: =IFERROR(INDEX($U$200:$AR$224,16,VLOOKUP($C$15,$I$100:$T$103,12,FALSE())+6),"") -> Same-month kill! +$40/mo.
B40: =IFERROR(INDEX($U$200:$AR$224,17,VLOOKUP($C$15,$I$100:$T$103,12,FALSE())+1),"") -> 17 | C40: =IFERROR(INDEX($U$200:$AR$224,17,VLOOKUP($C$15,$I$100:$T$103,12,FALSE())+2),"") -> Chase Amazon Prime Visa | D40: =IFERROR(INDEX($U$200:$AR$224,17,VLOOKUP($C$15,$I$100:$T$103,12,FALSE())+3),"") -> 46388 | E40: =IFERROR(INDEX($U$200:$AR$224,17,VLOOKUP($C$15,$I$100:$T$103,12,FALSE())+4),"") -> 654.42 | F40: =IFERROR(INDEX($U$200:$AR$224,17,VLOOKUP($C$15,$I$100:$T$103,12,FALSE())+5),"") -> 708.41 | G40: =IFERROR(INDEX($U$200:$AR$224,17,VLOOKUP($C$15,$I$100:$T$103,12,FALSE())+6),"") -> Same-month kill! +$54/mo.
B41: =IFERROR(INDEX($U$200:$AR$224,18,VLOOKUP($C$15,$I$100:$T$103,12,FALSE())+1),"") -> 18 | C41: =IFERROR(INDEX($U$200:$AR$224,18,VLOOKUP($C$15,$I$100:$T$103,12,FALSE())+2),"") -> Apple Card (Goldman Sachs) | D41: =IFERROR(INDEX($U$200:$AR$224,18,VLOOKUP($C$15,$I$100:$T$103,12,FALSE())+3),"") -> 46419 | E41: =IFERROR(INDEX($U$200:$AR$224,18,VLOOKUP($C$15,$I$100:$T$103,12,FALSE())+4),"") -> 7477.57 | F41: =IFERROR(INDEX($U$200:$AR$224,18,VLOOKUP($C$15,$I$100:$T$103,12,FALSE())+5),"") -> 7743.07 | G41: =IFERROR(INDEX($U$200:$AR$224,18,VLOOKUP($C$15,$I$100:$T$103,12,FALSE())+6),"") -> Big payoff — $266/mo joins war chest.
B42: =IFERROR(INDEX($U$200:$AR$224,19,VLOOKUP($C$15,$I$100:$T$103,12,FALSE())+1),"") -> 19 | C42: =IFERROR(INDEX($U$200:$AR$224,19,VLOOKUP($C$15,$I$100:$T$103,12,FALSE())+2),"") -> Affirm — Ridge | D42: =IFERROR(INDEX($U$200:$AR$224,19,VLOOKUP($C$15,$I$100:$T$103,12,FALSE())+3),"") -> 46419 | E42: =IFERROR(INDEX($U$200:$AR$224,19,VLOOKUP($C$15,$I$100:$T$103,12,FALSE())+4),"") -> 504.15 | F42: =IFERROR(INDEX($U$200:$AR$224,19,VLOOKUP($C$15,$I$100:$T$103,12,FALSE())+5),"") -> 560.17 | G42: =IFERROR(INDEX($U$200:$AR$224,19,VLOOKUP($C$15,$I$100:$T$103,12,FALSE())+6),"") -> Same-month kill! +$56/mo.
B43: =IFERROR(INDEX($U$200:$AR$224,20,VLOOKUP($C$15,$I$100:$T$103,12,FALSE())+1),"") -> 20 | C43: =IFERROR(INDEX($U$200:$AR$224,20,VLOOKUP($C$15,$I$100:$T$103,12,FALSE())+2),"") -> Affirm — Target | D43: =IFERROR(INDEX($U$200:$AR$224,20,VLOOKUP($C$15,$I$100:$T$103,12,FALSE())+3),"") -> 46419 | E43: =IFERROR(INDEX($U$200:$AR$224,20,VLOOKUP($C$15,$I$100:$T$103,12,FALSE())+4),"") -> 183.47 | F43: =IFERROR(INDEX($U$200:$AR$224,20,VLOOKUP($C$15,$I$100:$T$103,12,FALSE())+5),"") -> 203.85 | G43: =IFERROR(INDEX($U$200:$AR$224,20,VLOOKUP($C$15,$I$100:$T$103,12,FALSE())+6),"") -> Same-month kill! +$20/mo.
...

Sheet Payments
A1: PAYMENTS & TRANSACTIONS
A2: Starting Balance: | C2: 2954.7 | D2: Current Balance: | E2: =IFERROR(LOOKUP(2,1/(F6:F505<>""),G6:G505),C2) -> 3408.09 | F2: Statement Date: | G2: 46141
A3: Log every transaction. Bulk-paste from bank CSV. Pick Type (Income/Expense) and Creditor for each row.
A5: # | B5: Date | C5: Description (from bank) | D5: Type | E5: Creditor / Category | F5: Amount | G5: Running Balance | H5: Notes / Match Rule | I5: Month | J5: Year
A6: 1 | B6: 46113 | C6: APPLECARD GSBANK PAYMENT 2228596 WEB ID: 9999999999 | D6: Expense | E6: Apple Card (Goldman Sachs) | F6: 227.5 | G6: 2727.2 | H6: APPLECARD GSBANK → Apple Card (Goldman Sachs) | I6: =IF(B6="","",TEXT(B6,"mmm")) -> Apr | J6: =IF(B6="","",YEAR(B6)) -> 2026
A7: 2 | B7: 46113 | C7: PAYPAL INST XFER DOORDASH MOOYAH WEB ID: PAYPALSI77 | D7: Expense | E7: DoorDash & Delivery | F7: 42.53 | G7: 2684.67 | H7: DOORDASH → DoorDash & Delivery | I7: =IF(B7="","",TEXT(B7,"mmm")) -> Apr | J7: =IF(B7="","",YEAR(B7)) -> 2026
A8: 3 | B8: 46113 | C8: VENMO PAYMENT 1049294046835 WEB ID: 3264681992 | D8: Expense | E8: Venmo Transfer | F8: 16.25 | G8: 2668.42 | H8: VENMO → Venmo Transfer | I8: =IF(B8="","",TEXT(B8,"mmm")) -> Apr | J8: =IF(B8="","",YEAR(B8)) -> 2026
A9: 4 | B9: 46113 | C9: CAPITAL ONE CRCARDPMT CA0CBEAA436C428 WEB ID: 9541719318 | D9: Expense | E9: Capital One Platinum | F9: 500 | G9: 2168.42 | H9: CAP ONE @ $500 → Capital One Platinum | I9: =IF(B9="","",TEXT(B9,"mmm")) -> Apr | J9: =IF(B9="","",YEAR(B9)) -> 2026
A10: 5 | B10: 46114 | C10: UPSTART NETWORK CORNING / 1028845 WEB ID: 45466061FN | D10: Expense | E10: Upstart Loan | F10: 1309.17 | G10: 859.25 | H10: UPSTART NETWORK → Upstart Loan | I10: =IF(B10="","",TEXT(B10,"mmm")) -> Apr | J10: =IF(B10="","",YEAR(B10)) -> 2026
A11: 6 | B11: 46114 | C11: AMERICAN EXPRESS ACH PMT W3556 WEB ID: 2005032111 | D11: Expense | E11: Amex Delta SkyMiles Gold | F11: 600 | G11: 259.25 | H11: AMEX @ $600 → Amex Delta SkyMiles Gold | I11: =IF(B11="","",TEXT(B11,"mmm")) -> Apr | J11: =IF(B11="","",YEAR(B11)) -> 2026
A12: 7 | B12: 46115 | C12: KFI STAFFING, LL PAYROLL PPD ID: 874304726 | D12: Income | E12: Hannah's Paycheck (KFI) | F12: 3909.8 | G12: 4169.05 | H12: KFI STAFFING → Hannah's Paycheck (KFI) | I12: =IF(B12="","",TEXT(B12,"mmm")) -> Apr | J12: =IF(B12="","",YEAR(B12)) -> 2026
A13: 8 | B13: 46115 | C13: STATE FARM RO 27 SFPP PPD ID: 9000307001 | D13: Expense | F13: 128.59 | G13: 4040.46 | H13: STATE FARM → Auto Insurance (State Farm) | I13: =IF(B13="","",TEXT(B13,"mmm")) -> Apr | J13: =IF(B13="","",YEAR(B13)) -> 2026
A14: 9 | B14: 46115 | C14: PAYPAL PURCHASE PLAYSTATION WEB ID: PAYPALSI77 | D14: Expense | E14: PayPal Credit (Brad) / Synchrony | F14: 18.98 | G14: 4021.48 | H14: PLAYSTATION → Gaming subs | I14: =IF(B14="","",TEXT(B14,"mmm")) -> Apr | J14: =IF(B14="","",YEAR(B14)) -> 2026
A15: 10 | B15: 46115 | C15: CAPITAL ONE CRCARDPMT CA040925E95DF6A WEB ID: 9541719318 | D15: Expense | E15: Capital One Platinum | F15: 91 | G15: 3930.48 | H15: CAP ONE @ $91 → Capital One Platinum | I15: =IF(B15="","",TEXT(B15,"mmm")) -> Apr | J15: =IF(B15="","",YEAR(B15)) -> 2026
A16: 11 | B16: 46115 | C16: FIGURE LENDING L FIGUREPAYM PPD ID: 1191069000 | D16: Expense | E16: HELOC (Figure) | F16: 677.4 | G16: 3253.08 | H16: FIGURE LENDING → HELOC (Figure) | I16: =IF(B16="","",TEXT(B16,"mmm")) -> Apr | J16: =IF(B16="","",YEAR(B16)) -> 2026
A17: 12 | B17: 46115 | C17: PAYPAL PURCHASE STITCHFIXIN WEB ID: PAYPALSI77 | D17: Expense | E17: PayPal Credit (Brad) / Synchrony | F17: 42.77 | G17: 3210.31 | H17: STITCHFIXIN → Clothing (Threadbeast/Stitch/Lulu) | I17: =IF(B17="","",TEXT(B17,"mmm")) -> Apr | J17: =IF(B17="","",YEAR(B17)) -> 2026
A18: 13 | B18: 46118 | C18: PAYPAL TRANSFER PPD ID: PAYPALSD11 | D18: Income | E18: PayPal Credit (Brad) / Synchrony | F18: 87.48 | G18: 3297.79 | H18: PAYPAL → PayPal Credit (Brad) / Synchrony | I18: =IF(B18="","",TEXT(B18,"mmm")) -> Apr | J18: =IF(B18="","",YEAR(B18)) -> 2026
A19: 14 | B19: 46118 | C19: PAYPAL TRANSFER PPD ID: PAYPALSD11 | D19: Income | E19: PayPal Credit (Brad) / Synchrony | F19: 69.29 | G19: 3367.08 | H19: PAYPAL → PayPal Credit (Brad) / Synchrony | I19: =IF(B19="","",TEXT(B19,"mmm")) -> Apr | J19: =IF(B19="","",YEAR(B19)) -> 2026
A20: 15 | B20: 46118 | C20: PAYPAL TRANSFER PPD ID: PAYPALSD11 | D20: Income | E20: PayPal Credit (Brad) / Synchrony | F20: 9.02 | G20: 3376.1 | H20: PAYPAL → PayPal Credit (Brad) / Synchrony | I20: =IF(B20="","",TEXT(B20,"mmm")) -> Apr | J20: =IF(B20="","",YEAR(B20)) -> 2026
A21: 16 | B21: 46118 | C21: PAYPAL TRANSFER PPD ID: PAYPALSD11 | D21: Income | E21: PayPal Credit (Brad) / Synchrony | F21: 3.92 | G21: 3380.02 | H21: PAYPAL → PayPal Credit (Brad) / Synchrony | I21: =IF(B21="","",TEXT(B21,"mmm")) -> Apr | J21: =IF(B21="","",YEAR(B21)) -> 2026
A22: 17 | B22: 46118 | C22: PAYPAL TRANSFER PPD ID: PAYPALSD11 | D22: Income | E22: PayPal Credit (Brad) / Synchrony | F22: 3.65 | G22: 3383.67 | H22: PAYPAL → PayPal Credit (Brad) / Synchrony | I22: =IF(B22="","",TEXT(B22,"mmm")) -> Apr | J22: =IF(B22="","",YEAR(B22)) -> 2026
A23: 18 | B23: 46118 | C23: PAYPAL TRANSFER PPD ID: PAYPALSD11 | D23: Income | E23: PayPal Credit (Brad) / Synchrony | F23: 2.85 | G23: 3386.52 | H23: PAYPAL → PayPal Credit (Brad) / Synchrony | I23: =IF(B23="","",TEXT(B23,"mmm")) -> Apr | J23: =IF(B23="","",YEAR(B23)) -> 2026
A24: 19 | B24: 46118 | C24: PAYPAL TRANSFER PPD ID: PAYPALSD11 | D24: Income | E24: PayPal Credit (Brad) / Synchrony | F24: 0.54 | G24: 3387.06 | H24: PAYPAL → PayPal Credit (Brad) / Synchrony | I24: =IF(B24="","",TEXT(B24,"mmm")) -> Apr | J24: =IF(B24="","",YEAR(B24)) -> 2026
A25: 20 | B25: 46118 | C25: STATE FARM RO 27 CPC-CLIENT PPD ID: 9000313004 | D25: Expense | F25: 121.54 | G25: 3265.52 | H25: STATE FARM → Auto Insurance (State Farm) | I25: =IF(B25="","",TEXT(B25,"mmm")) -> Apr | J25: =IF(B25="","",YEAR(B25)) -> 2026
A26: 21 | B26: 46118 | C26: Online Transfer to GMR ...0324 transaction#: 28716405797 04/06 | D26: Transfer | E26: Savings Transfer (out) | F26: -80 | G26: 3185.52 | H26: ONLINE TRANSFER TO → Savings Transfer (out) | I26: =IF(B26="","",TEXT(B26,"mmm")) -> Apr | J26: =IF(B26="","",YEAR(B26)) -> 2026
A27: 22 | B27: 46118 | C27: Online Transfer to GMR ...0324 transaction#: 28716411133 04/06 | D27: Transfer | E27: Savings Transfer (out) | F27: -10 | G27: 3175.52 | H27: ONLINE TRANSFER TO → Savings Transfer (out) | I27: =IF(B27="","",TEXT(B27,"mmm")) -> Apr | J27: =IF(B27="","",YEAR(B27)) -> 2026
A28: 23 | B28: 46118 | C28: Online Transfer to SAV ...9037 transaction#: 28716437177 04/06 | D28: Transfer | E28: Savings Transfer (out) | F28: -20 | G28: 3155.52 | H28: ONLINE TRANSFER TO → Savings Transfer (out) | I28: =IF(B28="","",TEXT(B28,"mmm")) -> Apr | J28: =IF(B28="","",YEAR(B28)) -> 2026
A29: 24 | B29: 46118 | C29: UW Credit Union Loan Pay 000001836855588 WEB ID: 1222528268 | D29: Expense | E29: Hannah's Car Payment (UW Credit Union) | F29: 651.55 | G29: 2503.97 | H29: UW CREDIT UNION → UW Credit Union (Hannah's Car) | I29: =IF(B29="","",TEXT(B29,"mmm")) -> Apr | J29: =IF(B29="","",YEAR(B29)) -> 2026
A30: 25 | B30: 46118 | C30: CHASE CREDIT CRD AUTOPAY PPD ID: 4760039224 | D30: Expense | E30: Chase Amazon Prime Visa | F30: 434.31 | G30: 2069.66 | H30: CHASE CREDIT CRD → Chase Amazon Prime Visa | I30: =IF(B30="","",TEXT(B30,"mmm")) -> Apr | J30: =IF(B30="","",YEAR(B30)) -> 2026
A31: 26 | B31: 46118 | C31: BEST BUY AUTO PYMT 721951705420517 WEB ID: CITIAUTFDR | D31: Expense | F31: 29 | G31: 2040.66 | H31: CITI → Best Buy / Citi | I31: =IF(B31="","",TEXT(B31,"mmm")) -> Apr | J31: =IF(B31="","",YEAR(B31)) -> 2026
A32: 27 | B32: 46118 | C32: PAYPAL PURCHASE STARBUCKS WEB ID: PAYPALSI77 | D32: Expense | E32: PayPal Credit (Brad) / Synchrony | F32: 15 | G32: 2025.66 | H32: STARBUCKS → Coffee (Starbucks, Dunkin) | I32: =IF(B32="","",TEXT(B32,"mmm")) -> Apr | J32: =IF(B32="","",YEAR(B32)) -> 2026
A33: 28 | B33: 46118 | C33: PAYPAL PURCHASE NINTENDOAME WEB ID: PAYPALSI77 | D33: Expense | E33: PayPal Credit (Brad) / Synchrony | F33: 4.21 | G33: 2021.45 | H33: PAYPAL → PayPal Credit (Brad) / Synchrony | I33: =IF(B33="","",TEXT(B33,"mmm")) -> Apr | J33: =IF(B33="","",YEAR(B33)) -> 2026
A34: 29 | B34: 46118 | C34: AMERICAN EXPRESS ACH PMT M9698 WEB ID: 2005032111 | D34: Expense | E34: Amex Delta SkyMiles Gold | F34: 402.82 | G34: 1618.63 | H34: AMEX @ $402.82 → Amex Delta SkyMiles Gold | I34: =IF(B34="","",TEXT(B34,"mmm")) -> Apr | J34: =IF(B34="","",YEAR(B34)) -> 2026
A35: 30 | B35: 46118 | C35: AMERICAN EXPRESS ACH PMT M9212 WEB ID: 2005032111 | D35: Expense | E35: Amex Delta SkyMiles Gold | F35: 85.01 | G35: 1533.62 | H35: AMERICAN EXPRESS → Amex Delta SkyMiles Gold | I35: =IF(B35="","",TEXT(B35,"mmm")) -> Apr | J35: =IF(B35="","",YEAR(B35)) -> 2026
A36: 31 | B36: 46119 | C36: TOYOTA ACH LEASE WEB 3L0Y0OBJS80I9FC WEB ID: 3953775816 | D36: Expense | E36: Toyota Lease | F36: 672.8 | G36: 860.82 | H36: TOYOTA ACH → Toyota Lease | I36: =IF(B36="","",TEXT(B36,"mmm")) -> Apr | J36: =IF(B36="","",YEAR(B36)) -> 2026
A37: 32 | B37: 46119 | C37: PAYPAL INST XFER 1049422616723 WEB ID: PAYPALSI77 | D37: Expense | E37: PayPal Credit (Brad) / Synchrony | F37: 105 | G37: 755.82 | H37: PAYPAL → PayPal Credit (Brad) / Synchrony | I37: =IF(B37="","",TEXT(B37,"mmm")) -> Apr | J37: =IF(B37="","",YEAR(B37)) -> 2026
A38: 33 | B38: 46120 | C38: BRGHTWHL* Aldo.. PURCHASE B ST-U6B8C1H0S5E2 WEB ID: 1800948598 | D38: Expense | E38: Shopping (Misc) | F38: 200 | G38: 555.82 | H38: BRGHTWHL → Shopping (Misc) | I38: =IF(B38="","",TEXT(B38,"mmm")) -> Apr | J38: =IF(B38="","",YEAR(B38)) -> 2026
A39: 34 | B39: 46120 | C39: DISCOVER E-PAYMENT 2877 WEB ID: 2510020270 | D39: Expense | E39: Discover | F39: 184.7 | G39: 371.12 | H39: DISCOVER → Discover | I39: =IF(B39="","",TEXT(B39,"mmm")) -> Apr | J39: =IF(B39="","",YEAR(B39)) -> 2026
A40: 35 | B40: 46121 | C40: EXACT SCIENCES PAYROLL PPD ID: 9111111103 | D40: Income | E40: Brad's Paycheck (Exact) | F40: 2274.43 | G40: 2645.55 | H40: EXACT SCIENCES → Brad's Paycheck (Exact) | I40: =IF(B40="","",TEXT(B40,"mmm")) -> Apr | J40: =IF(B40="","",YEAR(B40)) -> 2026
A41: 36 | B41: 46121 | C41: KWIK TRIP INC PAYMENT 000093008198591 WEB ID: 9161597801 | D41: Expense | E41: Gasoline (Kwik Trip / Woodmans) | F41: 200 | G41: 2445.55 | H41: KWIK TRIP → Gasoline (Kwik Trip / Woodmans) | I41: =IF(B41="","",TEXT(B41,"mmm")) -> Apr | J41: =IF(B41="","",YEAR(B41)) -> 2026
...

Sheet Forecast
A1: 📊 CASH FLOW FORECAST
A3: Today's Balance: | B3: =Payments!E2 -> 3408.09 | C3: Forecast Start: | D3: 46143 | E3: View: | F3: 90 days | I3: =IF(F3="30 days",30,IF(F3="60 days",60,IF(F3="90 days",90,IF(F3="180 days",180,365)))) -> 90
A5: 💵 Lowest Bal: | B5: =MIN(OFFSET($AH$200,0,0,$I$3,1)) -> 2571.91 | C5: 📈 Income: | D5: =SUM(OFFSET($AD$200,0,0,$I$3,1)) -> 40385.05 | E5: 📉 Expenses: | F5: =SUM(OFFSET($AE$200,0,0,$I$3,1)) -> 26733.91 | G5: 💳 Debt Pmt: | H5: =SUM(OFFSET($AF$200,0,0,$I$3,1)) -> 9572.72 | I5: 🎯 End: | J5: =INDEX($AH$200:$AH$564,$I$3) -> 7486.51
A7: 📅 DAILY FORECAST (next 90 days)
A9: Day | B9: Date | C9: Income | D9: Expense | E9: Debt Pmt | F9: Net | G9: Balance | H9: Warning | I9: Notes
A10: 1 | B10: =AB200 -> 46143 | C10: =AD200 -> 3819.79 | D10: =AE200 -> 601.16 | E10: =AF200 -> 557.5 | F10: =AG200 -> 2661.13 | G10: =AH200 -> 6069.22 | H10: =IF(G10<0,"🚨",IF(G10<500,"⚠",""))
A11: 2 | B11: =AB201 -> 46144 | C11: =AD201 -> 0 | D11: =AE201 -> 0 | E11: =AF201 -> 1309.17 | F11: =AG201 -> -1309.17 | G11: =AH201 -> 4760.05 | H11: =IF(G11<0,"🚨",IF(G11<500,"⚠",""))
A12: 3 | B12: =AB202 -> 46145 | C12: =AD202 -> 0 | D12: =AE202 -> 927.53 | E12: =AF202 -> 0 | F12: =AG202 -> -927.53 | G12: =AH202 -> 3832.52 | H12: =IF(G12<0,"🚨",IF(G12<500,"⚠",""))
A13: 4 | B13: =AB203 -> 46146 | C13: =AD203 -> 0 | D13: =AE203 -> 0 | E13: =AF203 -> 0 | F13: =AG203 -> 0 | G13: =AH203 -> 3832.52 | H13: =IF(G13<0,"🚨",IF(G13<500,"⚠",""))
A14: 5 | B14: =AB204 -> 46147 | C14: =AD204 -> 0 | D14: =AE204 -> 51.01 | E14: =AF204 -> 0 | F14: =AG204 -> -51.01 | G14: =AH204 -> 3781.51 | H14: =IF(G14<0,"🚨",IF(G14<500,"⚠",""))
A15: 6 | B15: =AB205 -> 46148 | C15: =AD205 -> 0 | D15: =AE205 -> 651.55 | E15: =AF205 -> 259.86 | F15: =AG205 -> -911.41 | G15: =AH205 -> 2870.1 | H15: =IF(G15<0,"🚨",IF(G15<500,"⚠",""))
A16: 7 | B16: =AB206 -> 46149 | C16: =AD206 -> 2274.42 | D16: =AE206 -> 672.8 | E16: =AF206 -> 8.25 | F16: =AG206 -> 1593.37 | G16: =AH206 -> 4463.47 | H16: =IF(G16<0,"🚨",IF(G16<500,"⚠",""))
A17: 8 | B17: =AB207 -> 46150 | C17: =AD207 -> 0 | D17: =AE207 -> 513.85 | E17: =AF207 -> 0 | F17: =AG207 -> -513.85 | G17: =AH207 -> 3949.62 | H17: =IF(G17<0,"🚨",IF(G17<500,"⚠",""))
A18: 9 | B18: =AB208 -> 46151 | C18: =AD208 -> 0 | D18: =AE208 -> 0 | E18: =AF208 -> 162 | F18: =AG208 -> -162 | G18: =AH208 -> 3787.62 | H18: =IF(G18<0,"🚨",IF(G18<500,"⚠",""))
A19: 10 | B19: =AB209 -> 46152 | C19: =AD209 -> 0 | D19: =AE209 -> 340.22 | E19: =AF209 -> 72.54 | F19: =AG209 -> -412.76 | G19: =AH209 -> 3374.86 | H19: =IF(G19<0,"🚨",IF(G19<500,"⚠",""))
A20: 11 | B20: =AB210 -> 46153 | C20: =AD210 -> 0 | D20: =AE210 -> 0 | E20: =AF210 -> 0 | F20: =AG210 -> 0 | G20: =AH210 -> 3374.86 | H20: =IF(G20<0,"🚨",IF(G20<500,"⚠",""))
A21: 12 | B21: =AB211 -> 46154 | C21: =AD211 -> 0 | D21: =AE211 -> 167.68 | E21: =AF211 -> 0 | F21: =AG211 -> -167.68 | G21: =AH211 -> 3207.18 | H21: =IF(G21<0,"🚨",IF(G21<500,"⚠",""))
... A99: 90 | B99: =AB289 -> 46232 | C99: =AD289 -> 0 | D99: =AE289 -> 237.58 | E99: =AF289 -> 206.43 | F99: =AG289 -> -444.01 | G99: =AH289 -> 7486.51 | H99: =IF(G99<0,"🚨",IF(G99<500,"⚠",""))
A101: 📆 WEEKLY ROLLUP (days 91-180)
A103: Wk# | B103: Week of | C103: Income | D103: Expense | E103: Debt Pmt | F103: Net | G103: End Bal | H103: Warning | I103: Notes
A104: 14 | B104: =$D$3+91 -> 46234 | C104: =SUM(AD291:AD297) -> 0 | D104: =SUM(AE291:AE297) -> 2231.25 | E104: =SUM(AF291:AF297) -> 1926.53 | F104: =C104-D104-E104 -> -4157.78 | G104: =AH297 -> 5603.15 | H104: =IF(G104<0,"🚨",IF(G104<500,"⚠",""))
A105: 15 | B105: =$D$3+98 -> 46241 | C105: =SUM(AD298:AD304) -> 6094.21 | D105: =SUM(AE298:AE304) -> 1694.55 | E105: =SUM(AF298:AF304) -> 160.79 | F105: =C105-D105-E105 -> 4238.87 | G105: =AH304 -> 9842.02 | H105: =IF(G105<0,"🚨",IF(G105<500,"⚠",""))
A106: 16 | B106: =$D$3+105 -> 46248 | C106: =SUM(AD305:AD311) -> 0 | D106: =SUM(AE305:AE311) -> 3792.57 | E106: =SUM(AF305:AF311) -> 553.49 | F106: =C106-D106-E106 -> -4346.06 | G106: =AH311 -> 5495.96 | H106: =IF(G106<0,"🚨",IF(G106<500,"⚠",""))
A107: 17 | B107: =$D$3+112 -> 46255 | C107: =SUM(AD312:AD318) -> 6094.21 | D107: =SUM(AE312:AE318) -> 802.02 | E107: =SUM(AF312:AF318) -> 80 | F107: =C107-D107-E107 -> 5212.19 | G107: =AH318 -> 10708.15 | H107: =IF(G107<0,"🚨",IF(G107<500,"⚠",""))
A108: 18 | B108: =$D$3+119 -> 46262 | C108: =SUM(AD319:AD325) -> 0 | D108: =SUM(AE319:AE325) -> 1766.27 | E108: =SUM(AF319:AF325) -> 1873.1 | F108: =C108-D108-E108 -> -3639.37 | G108: =AH325 -> 7068.78 | H108: =IF(G108<0,"🚨",IF(G108<500,"⚠",""))
A109: 19 | B109: =$D$3+126 -> 46269 | C109: =SUM(AD326:AD332) -> 6094.21 | D109: =SUM(AE326:AE332) -> 2229.43 | E109: =SUM(AF326:AF332) -> 134.78 | F109: =C109-D109-E109 -> 3730 | G109: =AH332 -> 10798.78 | H109: =IF(G109<0,"🚨",IF(G109<500,"⚠",""))
A110: 20 | B110: =$D$3+133 -> 46276 | C110: =SUM(AD333:AD339) -> 0 | D110: =SUM(AE333:AE339) -> 3960.25 | E110: =SUM(AF333:AF339) -> 426.26 | F110: =C110-D110-E110 -> -4386.51 | G110: =AH339 -> 6412.27 | H110: =IF(G110<0,"🚨",IF(G110<500,"⚠",""))
A111: 21 | B111: =$D$3+140 -> 46283 | C111: =SUM(AD340:AD346) -> 6094.21 | D111: =SUM(AE340:AE346) -> 802.02 | E111: =SUM(AF340:AF346) -> 287.23 | F111: =C111-D111-E111 -> 5004.96 | G111: =AH346 -> 11417.23 | H111: =IF(G111<0,"🚨",IF(G111<500,"⚠",""))
A112: 22 | B112: =$D$3+147 -> 46290 | C112: =SUM(AD347:AD353) -> 0 | D112: =SUM(AE347:AE353) -> 838.74 | E112: =SUM(AF347:AF353) -> 471.93 | F112: =C112-D112-E112 -> -1310.67 | G112: =AH353 -> 10106.56 | H112: =IF(G112<0,"🚨",IF(G112<500,"⚠",""))
A113: 23 | B113: =$D$3+154 -> 46297 | C113: =SUM(AD354:AD360) -> 6094.21 | D113: =SUM(AE354:AE360) -> 2816.74 | E113: =SUM(AF354:AF360) -> 1317.42 | F113: =C113-D113-E113 -> 1960.05 | G113: =AH360 -> 12066.61 | H113: =IF(G113<0,"🚨",IF(G113<500,"⚠",""))
A114: 24 | B114: =$D$3+161 -> 46304 | C114: =SUM(AD361:AD367) -> 0 | D114: =SUM(AE361:AE367) -> 3958.47 | E114: =SUM(AF361:AF367) -> 315.8 | F114: =C114-D114-E114 -> -4274.27 | G114: =AH367 -> 7792.34 | H114: =IF(G114<0,"🚨",IF(G114<500,"⚠",""))
A115: 25 | B115: =$D$3+168 -> 46311 | C115: =SUM(AD368:AD374) -> 6094.21 | D115: =SUM(AE368:AE374) -> 1043 | E115: =SUM(AF368:AF374) -> 430.23 | F115: =C115-D115-E115 -> 4620.98 | G115: =AH374 -> 12413.32 | H115: =IF(G115<0,"🚨",IF(G115<500,"⚠",""))
A116: 26 | B116: =$D$3+175 -> 46318 | C116: =SUM(AD375:AD381) -> 0 | D116: =SUM(AE375:AE381) -> 798.6 | E116: =SUM(AF375:AF381) -> 206.43 | F116: =C116-D116-E116 -> -1005.03 | G116: =AH381 -> 11408.29 | H116: =IF(G116<0,"🚨",IF(G116<500,"⚠",""))
A118: 🗓️ MONTHLY ROLLUP (months 7-12)
A120: Mo# | B120: Month | C120: Income | D120: Expense | E120: Debt Pmt | F120: Net | G120: End Bal | H120: Warning | I120: Notes
A121: 7 | B121: =EDATE($D$3,6) -> 46327 | C121: =SUMIF($AC$200:$AC$564,7,$AD$200:$AD$564) -> 12188.42 | D121: =SUMIF($AC$200:$AC$564,7,$AE$200:$AE$564) -> 8757.97 | E121: =SUMIF($AC$200:$AC$564,7,$AF$200:$AF$564) -> 2273.83 | F121: =C121-D121-E121 -> 1156.62 | G121: =LOOKUP(2,1/($AC$200:$AC$564=7),$AH$200:$AH$564) -> 15924.7 | H121: =IF(G121<0,"🚨",IF(G121<500,"⚠",""))
A122: 8 | B122: =EDATE($D$3,7) -> 46357 | C122: =SUMIF($AC$200:$AC$564,8,$AD$200:$AD$564) -> 14462.84 | D122: =SUMIF($AC$200:$AC$564,8,$AE$200:$AE$564) -> 8757.97 | E122: =SUMIF($AC$200:$AC$564,8,$AF$200:$AF$564) -> 2122.47 | F122: =C122-D122-E122 -> 3582.4 | G122: =LOOKUP(2,1/($AC$200:$AC$564=8),$AH$200:$AH$564) -> 19507.1 | H122: =IF(G122<0,"🚨",IF(G122<500,"⚠",""))
A123: 9 | B123: =EDATE($D$3,8) -> 46388 | C123: =SUMIF($AC$200:$AC$564,9,$AD$200:$AD$564) -> 12188.42 | D123: =SUMIF($AC$200:$AC$564,9,$AE$200:$AE$564) -> 9217.97 | E123: =SUMIF($AC$200:$AC$564,9,$AF$200:$AF$564) -> 1983.47 | F123: =C123-D123-E123 -> 986.98 | G123: =LOOKUP(2,1/($AC$200:$AC$564=9),$AH$200:$AH$564) -> 20494.08 | H123: =IF(G123<0,"🚨",IF(G123<500,"⚠",""))
A124: 10 | B124: =EDATE($D$3,9) -> 46419 | C124: =SUMIF($AC$200:$AC$564,10,$AD$200:$AD$564) -> 12188.42 | D124: =SUMIF($AC$200:$AC$564,10,$AE$200:$AE$564) -> 8520.39 | E124: =SUMIF($AC$200:$AC$564,10,$AF$200:$AF$564) -> 1472.94 | F124: =C124-D124-E124 -> 2195.09 | G124: =LOOKUP(2,1/($AC$200:$AC$564=10),$AH$200:$AH$564) -> 22689.17 | H124: =IF(G124<0,"🚨",IF(G124<500,"⚠",""))
A125: 11 | B125: =EDATE($D$3,10) -> 46447 | C125: =SUMIF($AC$200:$AC$564,11,$AD$200:$AD$564) -> 12188.42 | D125: =SUMIF($AC$200:$AC$564,11,$AE$200:$AE$564) -> 8757.97 | E125: =SUMIF($AC$200:$AC$564,11,$AF$200:$AF$564) -> 1623.35 | F125: =C125-D125-E125 -> 1807.1 | G125: =LOOKUP(2,1/($AC$200:$AC$564=11),$AH$200:$AH$564) -> 24496.27 | H125: =IF(G125<0,"🚨",IF(G125<500,"⚠",""))
...

Sheet Debt Tracker
A1: DEBT TRACKER — Avalanche-able debt only
A2: Excludes mortgage, HELOC, auto lease, student loan, business loan, BNPL micro-balances. Sorted by APR (highest first).
T3: ← Hidden amortization schedule (per-month projected balance per debt)
A4: # | B4: Creditor / Account | C4: Type | D4: APR | E4: Balance | F4: Min Pmt | G4: Auto-Paid? | H4: Source | I4: Statement Date | J4: Notes | K4: APR Status | L4: Eff Balance | M4: Eff Min Pmt | N4: Total Paid | O4: Interest Accrued | P4: Current Balance | Q4: Status | R4: Future Bal (12mo) | T4: M+1 | U4: M+2 | V4: M+3 | W4: M+4 | X4: M+5 | Y4: M+6 | Z4: M+7 | AA4: M+8 | AB4: M+9 | AC4: M+10 | AD4: M+11 | AE4: M+12
A5: 1 | B5: Ashley Furniture / Synchrony | C5: Store Card | D5: 0.3499 | E5: 933.82 | F5: 33 | G5: =IF(P5<=0.01,"Yes","No") -> No | H5: Statement | I5: 04/2026 | J5: DEFERRED INTEREST promo expires 09/28/27 — pay $918.57 promo balance in full before then. | K5: Confirmed | L5: =P5 -> 899.82 | M5: =IF(P5<=0.01,0,F5) -> 33 | N5: =IFERROR(SUMIFS(Payments!$F:$F,Payments!$E:$E,B5,Payments!$D:$D,"Expense"),0) -> 34 | O5: =IFERROR(MAX(0,DATEDIF(DATE(2026,5,1),TODAY(),"M"))*E5*D5/12,0) -> 0 | P5: =MAX(0,E5+O5-N5) -> 899.82 | Q5: =IF(P5<=0.01,"✓ PAID OFF",IF(P5<E5*0.1,"⚡ ALMOST","ACTIVE")) -> ACTIVE | R5: 0 | T5: 0 | U5: 0 | V5: 0 | W5: 0 | X5: 0 | Y5: 0 | Z5: 0 | AA5: 0 | AB5: 0 | AC5: 0 | AD5: 0 | AE5: 0
A6: 2 | B6: Mattress Firm / Synchrony Home | C6: Store Card | D6: 0.3499 | E6: 1583.49 | F6: 129 | G6: =IF(P6<=0.01,"Yes","No") -> No | H6: Statement | I6: 04/2026 | J6: Equal Pay promo $1,088 at 0% until paid off; $484 at 29.99% & 34.99%. | K6: Confirmed | L6: =P6 -> 1254.49 | M6: =IF(P6<=0.01,0,F6) -> 129 | N6: =IFERROR(SUMIFS(Payments!$F:$F,Payments!$E:$E,B6,Payments!$D:$D,"Expense"),0) -> 329 | O6: =IFERROR(MAX(0,DATEDIF(DATE(2026,5,1),TODAY(),"M"))*E6*D6/12,0) -> 0 | P6: =MAX(0,E6+O6-N6) -> 1254.49 | Q6: =IF(P6<=0.01,"✓ PAID OFF",IF(P6<E6*0.1,"⚡ ALMOST","ACTIVE")) -> ACTIVE | R6: 0 | T6: 0 | U6: 0 | V6: 0 | W6: 0 | X6: 0 | Y6: 0 | Z6: 0 | AA6: 0 | AB6: 0 | AC6: 0 | AD6: 0 | AE6: 0
A7: 3 | B7: Best Buy / Citi | C7: Store Card | D7: 0.2999 | E7: 1200 | F7: 29 | G7: =IF(P7<=0.01,"Yes","No") -> No | H7: Estimated | I7: — | J7: Both balance & APR estimated. Citi store cards typically 27-30%. | K7: Estimated | L7: =P7 -> 1200 | M7: =IF(P7<=0.01,0,F7) -> 29 | N7: =IFERROR(SUMIFS(Payments!$F:$F,Payments!$E:$E,B7,Payments!$D:$D,"Expense"),0) -> 0 | O7: =IFERROR(MAX(0,DATEDIF(DATE(2026,5,1),TODAY(),"M"))*E7*D7/12,0) -> 0 | P7: =MAX(0,E7+O7-N7) -> 1200 | Q7: =IF(P7<=0.01,"✓ PAID OFF",IF(P7<E7*0.1,"⚡ ALMOST","ACTIVE")) -> ACTIVE | R7: 0 | T7: 0 | U7: 0 | V7: 0 | W7: 0 | X7: 0 | Y7: 0 | Z7: 0 | AA7: 0 | AB7: 0 | AC7: 0 | AD7: 0 | AE7: 0
A8: 4 | B8: Capital One Platinum | C8: Credit Card | D8: 0.2874 | E8: 5930.94 | F8: 200 | G8: =IF(P8<=0.01,"Yes","No") -> No | H8: Statement | I8: 04/16/26 | J8: Has cash advance balance ~$740. | K8: Confirmed | L8: =P8 -> 5339.94 | M8: =IF(P8<=0.01,0,F8) -> 200 | N8: =IFERROR(SUMIFS(Payments!$F:$F,Payments!$E:$E,B8,Payments!$D:$D,"Expense"),0) -> 591 | O8: =IFERROR(MAX(0,DATEDIF(DATE(2026,5,1),TODAY(),"M"))*E8*D8/12,0) -> 0 | P8: =MAX(0,E8+O8-N8) -> 5339.94 | Q8: =IF(P8<=0.01,"✓ PAID OFF",IF(P8<E8*0.1,"⚡ ALMOST","ACTIVE")) -> ACTIVE | R8: 0 | T8: 5051.83 | U8: 1309.7 | V8: 0 | W8: 0 | X8: 0 | Y8: 0 | Z8: 0 | AA8: 0 | AB8: 0 | AC8: 0 | AD8: 0 | AE8: 0
A9: 5 | B9: Amex Delta SkyMiles Gold | C9: Credit Card | D9: 0.2849 | E9: 7294.06 | F9: 205.87 | G9: =IF(P9<=0.01,"Yes","No") -> No | H9: Statement | I9: 04/19/26 | J9: AutoPay enrolled at min. | K9: Confirmed | L9: =P9 -> 5483.5 | M9: =IF(P9<=0.01,0,F9) -> 205.87 | N9: =IFERROR(SUMIFS(Payments!$F:$F,Payments!$E:$E,B9,Payments!$D:$D,"Expense"),0) -> 1810.56 | O9: =IFERROR(MAX(0,DATEDIF(DATE(2026,5,1),TODAY(),"M"))*E9*D9/12,0) -> 0 | P9: =MAX(0,E9+O9-N9) -> 5483.5 | Q9: =IF(P9<=0.01,"✓ PAID OFF",IF(P9<E9*0.1,"⚡ ALMOST","ACTIVE")) -> ACTIVE | R9: 0 | T9: 5407.82 | U9: 5330.34 | V9: 2728.97 | W9: 0 | X9: 0 | Y9: 0 | Z9: 0 | AA9: 0 | AB9: 0 | AC9: 0 | AD9: 0 | AE9: 0
A10: 6 | B10: Menards Big Card (Cap One) | C10: Store Card | D10: 0.2849 | E10: 2758.32 | F10: 92 | G10: =IF(P10<=0.01,"Yes","No") -> No | H10: Statement | I10: 04/08/26 | J10: AutoPay enrolled at min. | K10: Confirmed | L10: =P10 -> 2758.32 | M10: =IF(P10<=0.01,0,F10) -> 92 | N10: =IFERROR(SUMIFS(Payments!$F:$F,Payments!$E:$E,B10,Payments!$D:$D,"Expense"),0) -> 0 | O10: =IFERROR(MAX(0,DATEDIF(DATE(2026,5,1),TODAY(),"M"))*E10*D10/12,0) -> 0 | P10: =MAX(0,E10+O10-N10) -> 2758.32 | Q10: =IF(P10<=0.01,"✓ PAID OFF",IF(P10<E10*0.1,"⚡ ALMOST","ACTIVE")) -> ACTIVE | R10: 0 | T10: 2731.81 | U10: 2704.66 | V10: 2676.88 | W10: 1373.2 | X10: 0 | Y10: 0 | Z10: 0 | AA10: 0 | AB10: 0 | AC10: 0 | AD10: 0 | AE10: 0
A11: 7 | B11: Amex Platinum (Pay Over Time) | C11: Charge POT | D11: 0.2849 | E11: 1406.09 | F11: 40 | G11: =IF(P11<=0.01,"Yes","No") -> No | H11: Statement | I11: 04/21/26 | J11: Pay Over Time balance. | K11: Confirmed | L11: =P11 -> 1106.09 | M11: =IF(P11<=0.01,0,F11) -> 40 | N11: =IFERROR(SUMIFS(Payments!$F:$F,Payments!$E:$E,B11,Payments!$D:$D,"Expense"),0) -> 300 | O11: =IFERROR(MAX(0,DATEDIF(DATE(2026,5,1),TODAY(),"M"))*E11*D11/12,0) -> 0 | P11: =MAX(0,E11+O11-N11) -> 1106.09 | Q11: =IF(P11<=0.01,"✓ PAID OFF",IF(P11<E11*0.1,"⚡ ALMOST","ACTIVE")) -> ACTIVE | R11: 0 | T11: 1092.35 | U11: 1078.28 | V11: 1063.88 | W11: 1049.14 | X11: 0 | Y11: 0 | Z11: 0 | AA11: 0 | AB11: 0 | AC11: 0 | AD11: 0 | AE11: 0
A12: 8 | B12: Affirm — Best Buy (Dec) | C12: BNPL | D12: 0.2832 | E12: 3020.12 | F12: 151.01 | G12: =IF(P12<=0.01,"Yes","No") -> No | H12: Affirm App | I12: — | J12: 20 pmts left. APR back-calculated from 24-mo cashflow ($151.01 × 24 vs $2,742.99 financed). | K12: Calculated | L12: =P12 -> 2869.11 | M12: =IF(P12<=0.01,0,F12) -> 151.01 | N12: =IFERROR(SUMIFS(Payments!$F:$F,Payments!$E:$E,B12,Payments!$D:$D,"Expense"),0) -> 151.01 | O12: =IFERROR(MAX(0,DATEDIF(DATE(2026,5,1),TODAY(),"M"))*E12*D12/12,0) -> 0 | P12: =MAX(0,E12+O12-N12) -> 2869.11 | Q12: =IF(P12<=0.01,"✓ PAID OFF",IF(P12<E12*0.1,"⚡ ALMOST","ACTIVE")) -> ACTIVE | R12: 0 | T12: 2785.81 | U12: 2700.55 | V12: 2613.27 | W12: 2523.93 | X12: 657.36 | Y12: 0 | Z12: 0 | AA12: 0 | AB12: 0 | AC12: 0 | AD12: 0 | AE12: 0
A13: 9 | B13: Affirm — Best Buy (Feb) | C13: BNPL | D13: 0.2817 | E13: 1160.62 | F13: 72.54 | G13: =IF(P13<=0.01,"Yes","No") -> No | H13: Affirm App | I13: — | J13: 16 pmts left. APR back-calculated (18-mo term). | K13: Calculated | L13: =P13 -> 1088.08 | M13: =IF(P13<=0.01,0,F13) -> 72.54 | N13: =IFERROR(SUMIFS(Payments!$F:$F,Payments!$E:$E,B13,Payments!$D:$D,"Expense"),0) -> 72.54 | O13: =IFERROR(MAX(0,DATEDIF(DATE(2026,5,1),TODAY(),"M"))*E13*D13/12,0) -> 0 | P13: =MAX(0,E13+O13-N13) -> 1088.08 | Q13: =IF(P13<=0.01,"✓ PAID OFF",IF(P13<E13*0.1,"⚡ ALMOST","ACTIVE")) -> ACTIVE | R13: 0 | T13: 1041.08 | U13: 992.98 | V13: 943.75 | W13: 893.37 | X13: 841.8 | Y13: 0 | Z13: 0 | AA13: 0 | AB13: 0 | AC13: 0 | AD13: 0 | AE13: 0
A14: 10 | B14: Capital One Quicksilver | C14: Credit Card | D14: 0.2824 | E14: 1169.64 | F14: 38 | G14: =IF(P14<=0.01,"Yes","No") -> No | H14: Statement | I14: 04/24/26 | J14: AutoPay enrolled at min. | K14: Confirmed | L14: =P14 -> 1135.64 | M14: =IF(P14<=0.01,0,F14) -> 38 | N14: =IFERROR(SUMIFS(Payments!$F:$F,Payments!$E:$E,B14,Payments!$D:$D,"Expense"),0) -> 34 | O14: =IFERROR(MAX(0,DATEDIF(DATE(2026,5,1),TODAY(),"M"))*E14*D14/12,0) -> 0 | P14: =MAX(0,E14+O14-N14) -> 1135.64 | Q14: =IF(P14<=0.01,"✓ PAID OFF",IF(P14<E14*0.1,"⚡ ALMOST","ACTIVE")) -> ACTIVE | R14: 0 | T14: 1124.37 | U14: 1112.83 | V14: 1101.01 | W14: 1088.92 | X14: 1076.55 | Y14: 0 | Z14: 0 | AA14: 0 | AB14: 0 | AC14: 0 | AD14: 0 | AE14: 0
A15: 11 | B15: Discover | C15: Credit Card | D15: 0.2799 | E15: 2758 | F15: 80 | G15: =IF(P15<=0.01,"Yes","No") -> No | H15: Activity only | I15: 04/27/26 | J15: Balance approximate — confirm next statement. | K15: Approx | L15: =P15 -> 2349 | M15: =IF(P15<=0.01,0,F15) -> 80 | N15: =IFERROR(SUMIFS(Payments!$F:$F,Payments!$E:$E,B15,Payments!$D:$D,"Expense"),0) -> 409 | O15: =IFERROR(MAX(0,DATEDIF(DATE(2026,5,1),TODAY(),"M"))*E15*D15/12,0) -> 0 | P15: =MAX(0,E15+O15-N15) -> 2349 | Q15: =IF(P15<=0.01,"✓ PAID OFF",IF(P15<E15*0.1,"⚡ ALMOST","ACTIVE")) -> ACTIVE | R15: 0 | T15: 2323.79 | U15: 2297.99 | V15: 2271.59 | W15: 2244.58 | X15: 2216.93 | Y15: 308.43 | Z15: 0 | AA15: 0 | AB15: 0 | AC15: 0 | AD15: 0 | AE15: 0
A16: 12 | B16: Credit One Bank | C16: Credit Card | D16: 0.2799 | E16: 300 | F16: 8.25 | G16: =IF(P16<=0.01,"Yes","No") -> No | H16: Estimated | I16: — | J16: Both balance & APR estimated. Credit One subprime cards typically 24-29%. | K16: Estimated | L16: =P16 -> 291.75 | M16: =IF(P16<=0.01,0,F16) -> 8.25 | N16: =IFERROR(SUMIFS(Payments!$F:$F,Payments!$E:$E,B16,Payments!$D:$D,"Expense"),0) -> 8.25 | O16: =IFERROR(MAX(0,DATEDIF(DATE(2026,5,1),TODAY(),"M"))*E16*D16/12,0) -> 0 | P16: =MAX(0,E16+O16-N16) -> 291.75 | Q16: =IF(P16<=0.01,"✓ PAID OFF",IF(P16<E16*0.1,"⚡ ALMOST","ACTIVE")) -> ACTIVE | R16: 0 | T16: 290.31 | U16: 288.83 | V16: 287.31 | W16: 285.76 | X16: 284.18 | Y16: 282.56 | Z16: 0 | AA16: 0 | AB16: 0 | AC16: 0 | AD16: 0 | AE16: 0
... A29: 25 | B29: Affirm — Target | C29: BNPL | D29: 0 | E29: 183.47 | F29: 20.38 | G29: =IF(P29<=0.01,"Yes","No") -> No | H29: Affirm App | I29: — | J29: 9 pmts left. 0% promo confirmed by math. | K29: Confirmed | L29: =P29 -> 163.09 | M29: =IF(P29<=0.01,0,F29) -> 20.38 | N29: =IFERROR(SUMIFS(Payments!$F:$F,Payments!$E:$E,B29,Payments!$D:$D,"Expense"),0) -> 20.38 | O29: =IFERROR(MAX(0,DATEDIF(DATE(2026,5,1),TODAY(),"M"))*E29*D29/12,0) -> 0 | P29: =MAX(0,E29+O29-N29) -> 163.09 | Q29: =IF(P29<=0.01,"✓ PAID OFF",IF(P29<E29*0.1,"⚡ ALMOST","ACTIVE")) -> ACTIVE | R29: 0 | T29: 142.71 | U29: 122.33 | V29: 101.95 | W29: 81.57 | X29: 61.19 | Y29: 40.81 | Z29: 20.43 | AA29: 0.05 | AB29: 0 | AC29: 0 | AD29: 0 | AE29: 0
B30: TOTALS | E30: =SUM(E5:E29) -> 85141.66 | F30: =SUM(F5:F29) -> 3318.24 | J30: ← Total avalanche-able debt | Total min pmts → | L30: =SUM(L5:L29) -> 78762.38 | M30: =SUM(M5:M29) -> 3318.24 | N30: =SUM(N5:N29) -> 6379.28 | O30: =SUM(O5:O29) -> 0 | P30: =SUM(P5:P29) -> 78762.38 | R30: =SUM(R5:R29) -> 6908.58
B32: Quick Stats:
B33: Avalanche Target: | C33: =INDEX(B5:B29,MATCH(MAX(D5:D29),D5:D29,0)) -> Ashley Furniture / Synchrony
B34: Target APR: | C34: =MAX(D5:D29) -> 0.3499
B35: Target Balance: | C35: =INDEX(E5:E29,MATCH(MAX(D5:D29),D5:D29,0)) -> 933.82
B36: # of Debts: | C36: 25
B37: Weighted Avg APR: | C37: =SUMPRODUCT(D5:D29,E5:E29)/SUM(E5:E29) -> 0.22788768
B39: APR Status Legend:
B40: Confirmed | C40: From statement — accurate
B41: Calculated | C41: Back-calculated from payment math
B42: Approx | C42: Approximate — should be confirmed
B43: Placeholder | C43: 15% placeholder for 0% Affirm promos (deferred-interest hedge)
B44: Estimated | C44: My guess — replace with actual when known

Sheet Avalanche Projection
A1: AVALANCHE PROJECTION
B3: Net Surplus from Budget: | C3: ='Monthly Budget'!C126 -> 3472.12 | D3: ← Live from Monthly Budget | F3: 📸 SIMULATION SNAPSHOT
B4: Mode: | C4: Budgeted | D4: ← 'Budgeted' uses C126; 'Actual' uses D126 | F4: Computed: 04/30/2026 01:21
B5: Effective Extra/Month: | C5: =IF(C4="Actual",MAX(0,'Monthly Budget'!D126),MAX(0,C3)) -> 3472.12 | D5: ← Negative→0 | F5: Extra used: $3,472.12/mo
A7: 🎯 KEY METRICS — WITH AVALANCHE STRATEGY
B8: Total Debt (Active): | C8: ='Debt Tracker'!L30 -> 78762.38 | E8: Total Min Pmts/mo: | F8: ='Debt Tracker'!M30 -> 3318.24
B9: Months to Debt-Free: | C9: 23 | E9: Debt-Free Date: | F9: 46813
B10: Total Interest Paid: | C10: 18221.486 | E10: Years to Debt-Free: | F10: 1.9166667
B11: Avalanche Target Now: | C11: Mattress Firm / Synchrony Home | E11: Target APR / Balance: | F11: 34.99% / $1,583
A13: 🎯 YOUR NEXT 3 MOVES
A14: Step | B14: Target Debt | C14: APR | D14: Pay Off By | E14: From Month | F14: Pmt Frees Up | H14: What to do
A15: #1 | B15: Mattress Firm / Synchrony Home | C15: 0.3499 | D15: 46143 | E15: Mo 1–1 | F15: 129 | H15: Send all extra (~$3,472/mo) here NOW. Combine with min pmt.
A16: #2 | B16: Ashley Furniture / Synchrony | C16: 0.3499 | D16: 46174 | E16: Mo 2–2 | F16: 33 | H16: After #1 dies, redirect freed $$ here.
A17: #3 | B17: Best Buy / Citi | C17: 0.2999 | D17: 46204 | E17: Mo 3–3 | F17: 29 | H17: After #2 dies, redirect freed $$ here.
A18: DEBT QUEUE — AVALANCHE PAYOFF ORDER
A19: Order | B19: Creditor | C19: APR | D19: Balance | E19: Min Pmt | F19: Months Solo | G19: Interest if Min Only | H19: Status
A20: 1 | B20: ='Debt Tracker'!B6 -> Mattress Firm / Synchrony Home | C20: ='Debt Tracker'!D6 -> 0.3499 | D20: ='Debt Tracker'!L6 -> 1254.49 | E20: ='Debt Tracker'!M6 -> 129 | F20: =IF(D15<=0.01,"—",IFERROR(IF(E15<=D15*C15/12,"⚠ NEVER",CEILING(NPER(C15/12,-E15,D15),1)),"—")) -> — | G20: =IFERROR(IF(D15<=0.01,0,IF(E15<=D15*C15/12,"—",(E15*F15)-D15)),"—") -> — | H20: =IF('Debt Tracker'!G6="Yes","Paid Off",IF(D15<=0.01,"Zero","Active")) -> Active
A21: 2 | B21: ='Debt Tracker'!B5 -> Ashley Furniture / Synchrony | C21: ='Debt Tracker'!D5 -> 0.3499 | D21: ='Debt Tracker'!L5 -> 899.82 | E21: ='Debt Tracker'!M5 -> 33 | F21: =IF(D16<=0.01,"—",IFERROR(IF(E16<=D16*C16/12,"⚠ NEVER",CEILING(NPER(C16/12,-E16,D16),1)),"—")) -> — | G21: =IFERROR(IF(D16<=0.01,0,IF(E16<=D16*C16/12,"—",(E16*F16)-D16)),"—") -> — | H21: =IF('Debt Tracker'!G5="Yes","Paid Off",IF(D16<=0.01,"Zero","Active")) -> Active
A22: 3 | B22: ='Debt Tracker'!B7 -> Best Buy / Citi | C22: ='Debt Tracker'!D7 -> 0.2999 | D22: ='Debt Tracker'!L7 -> 1200 | E22: ='Debt Tracker'!M7 -> 29 | F22: =IF(D17<=0.01,"—",IFERROR(IF(E17<=D17*C17/12,"⚠ NEVER",CEILING(NPER(C17/12,-E17,D17),1)),"—")) -> — | G22: =IFERROR(IF(D17<=0.01,0,IF(E17<=D17*C17/12,"—",(E17*F17)-D17)),"—") -> — | H22: =IF('Debt Tracker'!G7="Yes","Paid Off",IF(D17<=0.01,"Zero","Active")) -> Active
A23: 4 | B23: ='Debt Tracker'!B8 -> Capital One Platinum | C23: ='Debt Tracker'!D8 -> 0.2874 | D23: ='Debt Tracker'!L8 -> 5339.94 | E23: ='Debt Tracker'!M8 -> 200 | F23: =IF(D18<=0.01,"—",IFERROR(IF(E18<=D18*C18/12,"⚠ NEVER",CEILING(NPER(C18/12,-E18,D18),1)),"—")) -> — | G23: =IFERROR(IF(D18<=0.01,0,IF(E18<=D18*C18/12,"—",(E18*F18)-D18)),"—") -> 0 | H23: =IF('Debt Tracker'!G8="Yes","Paid Off",IF(D18<=0.01,"Zero","Active")) -> Zero
A24: 5 | B24: ='Debt Tracker'!B9 -> Amex Delta SkyMiles Gold | C24: ='Debt Tracker'!D9 -> 0.2849 | D24: ='Debt Tracker'!L9 -> 5483.5 | E24: ='Debt Tracker'!M9 -> 205.87 | F24: =IF(D19<=0.01,"—",IFERROR(IF(E19<=D19*C19/12,"⚠ NEVER",CEILING(NPER(C19/12,-E19,D19),1)),"—")) -> — | G24: =IFERROR(IF(D19<=0.01,0,IF(E19<=D19*C19/12,"—",(E19*F19)-D19)),"—") -> — | H24: =IF('Debt Tracker'!G9="Yes","Paid Off",IF(D19<=0.01,"Zero","Active")) -> Active
A25: 6 | B25: ='Debt Tracker'!B10 -> Menards Big Card (Cap One) | C25: ='Debt Tracker'!D10 -> 0.2849 | D25: ='Debt Tracker'!L10 -> 2758.32 | E25: ='Debt Tracker'!M10 -> 92 | F25: =IF(D20<=0.01,"—",IFERROR(IF(E20<=D20*C20/12,"⚠ NEVER",CEILING(NPER(C20/12,-E20,D20),1)),"—")) -> 12 | G25: =IFERROR(IF(D20<=0.01,0,IF(E20<=D20*C20/12,"—",(E20*F20)-D20)),"—") -> — | H25: =IF('Debt Tracker'!G10="Yes","Paid Off",IF(D20<=0.01,"Zero","Active")) -> Active
A26: 7 | B26: ='Debt Tracker'!B11 -> Amex Platinum (Pay Over Time) | C26: ='Debt Tracker'!D11 -> 0.2849 | D26: ='Debt Tracker'!L11 -> 1106.09 | E26: ='Debt Tracker'!M11 -> 40 | F26: =IF(D21<=0.01,"—",IFERROR(IF(E21<=D21*C21/12,"⚠ NEVER",CEILING(NPER(C21/12,-E21,D21),1)),"—")) -> 56 | G26: =IFERROR(IF(D21<=0.01,0,IF(E21<=D21*C21/12,"—",(E21*F21)-D21)),"—") -> — | H26: =IF('Debt Tracker'!G11="Yes","Paid Off",IF(D21<=0.01,"Zero","Active")) -> Active
A27: 8 | B27: ='Debt Tracker'!B12 -> Affirm — Best Buy (Dec) | C27: ='Debt Tracker'!D12 -> 0.2832 | D27: ='Debt Tracker'!L12 -> 2869.11 | E27: ='Debt Tracker'!M12 -> 151.01 | F27: =IF(D22<=0.01,"—",IFERROR(IF(E22<=D22*C22/12,"⚠ NEVER",CEILING(NPER(C22/12,-E22,D22),1)),"—")) -> ⚠ NEVER | G27: =IFERROR(IF(D22<=0.01,0,IF(E22<=D22*C22/12,"—",(E22*F22)-D22)),"—") -> — | H27: =IF('Debt Tracker'!G12="Yes","Paid Off",IF(D22<=0.01,"Zero","Active")) -> Active
A28: 9 | B28: ='Debt Tracker'!B14 -> Capital One Quicksilver | C28: ='Debt Tracker'!D14 -> 0.2824 | D28: ='Debt Tracker'!L14 -> 1135.64 | E28: ='Debt Tracker'!M14 -> 38 | F28: =IF(D23<=0.01,"—",IFERROR(IF(E23<=D23*C23/12,"⚠ NEVER",CEILING(NPER(C23/12,-E23,D23),1)),"—")) -> 44 | G28: =IFERROR(IF(D23<=0.01,0,IF(E23<=D23*C23/12,"—",(E23*F23)-D23)),"—") -> — | H28: =IF('Debt Tracker'!G14="Yes","Paid Off",IF(D23<=0.01,"Zero","Active")) -> Active
A29: 10 | B29: ='Debt Tracker'!B13 -> Affirm — Best Buy (Feb) | C29: ='Debt Tracker'!D13 -> 0.2817 | D29: ='Debt Tracker'!L13 -> 1088.08 | E29: ='Debt Tracker'!M13 -> 72.54 | F29: =IF(D24<=0.01,"—",IFERROR(IF(E24<=D24*C24/12,"⚠ NEVER",CEILING(NPER(C24/12,-E24,D24),1)),"—")) -> 43 | G29: =IFERROR(IF(D24<=0.01,0,IF(E24<=D24*C24/12,"—",(E24*F24)-D24)),"—") -> — | H29: =IF('Debt Tracker'!G13="Yes","Paid Off",IF(D24<=0.01,"Zero","Active")) -> Active
A30: 11 | B30: ='Debt Tracker'!B15 -> Discover | C30: ='Debt Tracker'!D15 -> 0.2799 | D30: ='Debt Tracker'!L15 -> 2349 | E30: ='Debt Tracker'!M15 -> 80 | F30: =IF(D25<=0.01,"—",IFERROR(IF(E25<=D25*C25/12,"⚠ NEVER",CEILING(NPER(C25/12,-E25,D25),1)),"—")) -> 54 | G30: =IFERROR(IF(D25<=0.01,0,IF(E25<=D25*C25/12,"—",(E25*F25)-D25)),"—") -> -1654.32 | H30: =IF('Debt Tracker'!G15="Yes","Paid Off",IF(D25<=0.01,"Zero","Active")) -> Active
A31: 12 | B31: ='Debt Tracker'!B16 -> Credit One Bank | C31: ='Debt Tracker'!D16 -> 0.2799 | D31: ='Debt Tracker'!L16 -> 291.75 | E31: ='Debt Tracker'!M16 -> 8.25 | F31: =IF(D26<=0.01,"—",IFERROR(IF(E26<=D26*C26/12,"⚠ NEVER",CEILING(NPER(C26/12,-E26,D26),1)),"—")) -> 46 | G31: =IFERROR(IF(D26<=0.01,0,IF(E26<=D26*C26/12,"—",(E26*F26)-D26)),"—") -> 1133.91 | H31: =IF('Debt Tracker'!G16="Yes","Paid Off",IF(D26<=0.01,"Zero","Active")) -> Active
A32: 13 | B32: ='Debt Tracker'!B18 -> PayPal Credit (Hannah) / Synchrony | C32: ='Debt Tracker'!D18 -> 0.2749 | D32: ='Debt Tracker'!L18 -> 3116.13 | E32: ='Debt Tracker'!M18 -> 99 | F32: =IF(D27<=0.01,"—",IFERROR(IF(E27<=D27*C27/12,"⚠ NEVER",CEILING(NPER(C27/12,-E27,D27),1)),"—")) -> 26 | G32: =IFERROR(IF(D27<=0.01,0,IF(E27<=D27*C27/12,"—",(E27*F27)-D27)),"—") -> — | H32: =IF('Debt Tracker'!G18="Yes","Paid Off",IF(D27<=0.01,"Zero","Active")) -> Active
A33: 14 | B33: ='Debt Tracker'!B17 -> PayPal Credit (Brad) / Synchrony | C33: ='Debt Tracker'!D17 -> 0.2749 | D33: ='Debt Tracker'!L17 -> 1254.15 | E33: ='Debt Tracker'!M17 -> 44 | F33: =IF(D28<=0.01,"—",IFERROR(IF(E28<=D28*C28/12,"⚠ NEVER",CEILING(NPER(C28/12,-E28,D28),1)),"—")) -> 53 | G33: =IFERROR(IF(D28<=0.01,0,IF(E28<=D28*C28/12,"—",(E28*F28)-D28)),"—") -> 536.36 | H33: =IF('Debt Tracker'!G17="Yes","Paid Off",IF(D28<=0.01,"Zero","Active")) -> Active
A34: 15 | B34: ='Debt Tracker'!B19 -> Affirm — Shady Rays | C34: ='Debt Tracker'!D19 -> 0.2697 | D34: ='Debt Tracker'!L19 -> 114.71 | E34: ='Debt Tracker'!M19 -> 19.11 | F34: =IF(D29<=0.01,"—",IFERROR(IF(E29<=D29*C29/12,"⚠ NEVER",CEILING(NPER(C29/12,-E29,D29),1)),"—")) -> 19 | G34: =IFERROR(IF(D29<=0.01,0,IF(E29<=D29*C29/12,"—",(E29*F29)-D29)),"—") -> 2031.14 | H34: =IF('Debt Tracker'!G19="Yes","Paid Off",IF(D29<=0.01,"Zero","Active")) -> Active
A35: 16 | B35: ='Debt Tracker'!B20 -> Amex Blue Cash Preferred | C35: ='Debt Tracker'!D20 -> 0.2649 | D35: ='Debt Tracker'!L20 -> 1015.61 | E35: ='Debt Tracker'!M20 -> 40 | F35: =IF(D30<=0.01,"—",IFERROR(IF(E30<=D30*C30/12,"⚠ NEVER",CEILING(NPER(C30/12,-E30,D30),1)),"—")) -> 51 | G35: =IFERROR(IF(D30<=0.01,0,IF(E30<=D30*C30/12,"—",(E30*F30)-D30)),"—") -> 1971 | H35: =IF('Debt Tracker'!G20="Yes","Paid Off",IF(D30<=0.01,"Zero","Active")) -> Active
A36: 17 | B36: ='Debt Tracker'!B21 -> Chase Amazon Prime Visa | C36: ='Debt Tracker'!D21 -> 0.2649 | D36: ='Debt Tracker'!L21 -> 220.11 | E36: ='Debt Tracker'!M21 -> 53.99 | F36: =IF(D31<=0.01,"—",IFERROR(IF(E31<=D31*C31/12,"⚠ NEVER",CEILING(NPER(C31/12,-E31,D31),1)),"—")) -> 76 | G36: =IFERROR(IF(D31<=0.01,0,IF(E31<=D31*C31/12,"—",(E31*F31)-D31)),"—") -> 87.75 | H36: =IF('Debt Tracker'!G21="Yes","Paid Off",IF(D31<=0.01,"Zero","Active")) -> Active
A37: 18 | B37: ='Debt Tracker'!B22 -> Apple Card (Goldman Sachs) | C37: ='Debt Tracker'!D22 -> 0.2549 | D37: ='Debt Tracker'!L22 -> 7250.07 | E37: ='Debt Tracker'!M22 -> 265.5 | F37: =IF(D32<=0.01,"—",IFERROR(IF(E32<=D32*C32/12,"⚠ NEVER",CEILING(NPER(C32/12,-E32,D32),1)),"—")) -> 57 | G37: =IFERROR(IF(D32<=0.01,0,IF(E32<=D32*C32/12,"—",(E32*F32)-D32)),"—") -> -542.13 | H37: =IF('Debt Tracker'!G22="Yes","Paid Off",IF(D32<=0.01,"Zero","Active")) -> Active
A38: 19 | B38: ='Debt Tracker'!B23 -> Upstart Loan | C38: ='Debt Tracker'!D23 -> 0.18 | D38: ='Debt Tracker'!L23 -> 30690.83 | E38: ='Debt Tracker'!M23 -> 1309.17 | F38: =IF(D33<=0.01,"—",IFERROR(IF(E33<=D33*C33/12,"⚠ NEVER",CEILING(NPER(C33/12,-E33,D33),1)),"—")) -> 47 | G38: =IFERROR(IF(D33<=0.01,0,IF(E33<=D33*C33/12,"—",(E33*F33)-D33)),"—") -> 1077.85 | H38: =IF('Debt Tracker'!G23="Yes","Paid Off",IF(D33<=0.01,"Zero","Active")) -> Active
A39: 20 | B39: ='Debt Tracker'!B24 -> Affirm — Tonal | C39: ='Debt Tracker'!D24 -> 0.15 | D39: ='Debt Tracker'!L24 -> 4045.32 | E39: ='Debt Tracker'!M24 -> 139.5 | F39: =IF(D34<=0.01,"—",IFERROR(IF(E34<=D34*C34/12,"⚠ NEVER",CEILING(NPER(C34/12,-E34,D34),1)),"—")) -> 7 | G39: =IFERROR(IF(D34<=0.01,0,IF(E34<=D34*C34/12,"—",(E34*F34)-D34)),"—") -> 248.38 | H39: =IF('Debt Tracker'!G24="Yes","Paid Off",IF(D34<=0.01,"Zero","Active")) -> Active
A40: 21 | B40: ='Debt Tracker'!B25 -> Affirm — Peloton | C40: ='Debt Tracker'!D25 -> 0.15 | D40: ='Debt Tracker'!L25 -> 3446.11 | E40: ='Debt Tracker'!M25 -> 107.75 | F40: =IF(D35<=0.01,"—",IFERROR(IF(E35<=D35*C35/12,"⚠ NEVER",CEILING(NPER(C35/12,-E35,D35),1)),"—")) -> 38 | G40: =IFERROR(IF(D35<=0.01,0,IF(E35<=D35*C35/12,"—",(E35*F35)-D35)),"—") -> 1024.39 | H40: =IF('Debt Tracker'!G25="Yes","Paid Off",IF(D35<=0.01,"Zero","Active")) -> Active
A41: 22 | B41: ='Debt Tracker'!B26 -> Affirm — Amazon | C41: ='Debt Tracker'!D26 -> 0.15 | D41: ='Debt Tracker'!L26 -> 1002.44 | E41: ='Debt Tracker'!M26 -> 66.93 | F41: =IF(D36<=0.01,"—",IFERROR(IF(E36<=D36*C36/12,"⚠ NEVER",CEILING(NPER(C36/12,-E36,D36),1)),"—")) -> 5 | G41: =IFERROR(IF(D36<=0.01,0,IF(E36<=D36*C36/12,"—",(E36*F36)-D36)),"—") -> 3883.13 | H41: =IF('Debt Tracker'!G26="Yes","Paid Off",IF(D36<=0.01,"Zero","Active")) -> Active
A42: 23
A43: 24 | B43: ='Debt Tracker'!B29 -> Affirm — Target | C43: ='Debt Tracker'!D29 -> 0 | D43: ='Debt Tracker'!L29 -> 163.09 | E43: ='Debt Tracker'!M29 -> 20.38 | F43: =IF(D38<=0.01,"—",IFERROR(IF(E38<=D38*C38/12,"⚠ NEVER",CEILING(NPER(C38/12,-E38,D38),1)),"—")) -> 30 | G43: =IFERROR(IF(D38<=0.01,0,IF(E38<=D38*C38/12,"—",(E38*F38)-D38)),"—") -> 30840.16 | H43: =IF('Debt Tracker'!G29="Yes","Paid Off",IF(D38<=0.01,"Zero","Active")) -> Active
...

Sheet Savings Impact
A1: SAVINGS IMPACT SIMULATOR
B3: Available Savings: | C3: 23000 | D3: ← Edit your savings amount
B4: Cost of Selected: | C4: =G42 -> 0
B5: Savings Remaining: | C5: =C3-C4 -> 23000 | D5: ← If negative, you've selected more than you have
A7: 📊 BASELINE — KEEP SAVINGS IN BANK
B8: Months to Debt-Free: | C8: 23 | E8: Total Interest: | F8: 18221.486
B9: Debt-Free Date: | C9: 46813 | E9: Years: | F9: 1.9166667
A11: ✨ SCENARIO — DEPLOY SAVINGS TO PAY OFF SELECTED DEBTS
B12: Months to Debt-Free: | C12: "Re-run sim" | E12: Total Interest: | F12: "Re-run sim"
B13: MONTHS SAVED: | C13: "Re-run sim" | E13: INTEREST SAVED: | F13: "Re-run sim"
A15: SELECT DEBTS TO PAY OFF WITH SAVINGS — Mark 'Yes' to pay off, 'No' to keep
A16: # | B16: Creditor | C16: APR | D16: Balance | E16: Min Pmt | F16: Use Savings? | G16: Cost | H16: Cumulative Cost
A17: 1 | B17: ='Debt Tracker'!B6 -> Mattress Firm / Synchrony Home | C17: ='Debt Tracker'!D6 -> 0.3499 | D17: ='Debt Tracker'!L6 -> 1254.49 | E17: ='Debt Tracker'!M6 -> 129 | F17: No | G17: =IF(F17="Yes",D17,0) -> 0 | H17: =G17 -> 0
A18: 2 | B18: ='Debt Tracker'!B5 -> Ashley Furniture / Synchrony | C18: ='Debt Tracker'!D5 -> 0.3499 | D18: ='Debt Tracker'!L5 -> 899.82 | E18: ='Debt Tracker'!M5 -> 33 | F18: No | G18: =IF(F18="Yes",D18,0) -> 0 | H18: =H17+G18 -> 0
A19: 3 | B19: ='Debt Tracker'!B7 -> Best Buy / Citi | C19: ='Debt Tracker'!D7 -> 0.2999 | D19: ='Debt Tracker'!L7 -> 1200 | E19: ='Debt Tracker'!M7 -> 29 | F19: No | G19: =IF(F19="Yes",D19,0) -> 0 | H19: =H18+G19 -> 0
A20: 4 | B20: ='Debt Tracker'!B8 -> Capital One Platinum | C20: ='Debt Tracker'!D8 -> 0.2874 | D20: ='Debt Tracker'!L8 -> 5339.94 | E20: ='Debt Tracker'!M8 -> 200 | F20: No | G20: =IF(F20="Yes",D20,0) -> 0 | H20: =H19+G20 -> 0
A21: 5 | B21: ='Debt Tracker'!B9 -> Amex Delta SkyMiles Gold | C21: ='Debt Tracker'!D9 -> 0.2849 | D21: ='Debt Tracker'!L9 -> 5483.5 | E21: ='Debt Tracker'!M9 -> 205.87 | F21: No | G21: =IF(F21="Yes",D21,0) -> 0 | H21: =H20+G21 -> 0
A22: 6 | B22: ='Debt Tracker'!B10 -> Menards Big Card (Cap One) | C22: ='Debt Tracker'!D10 -> 0.2849 | D22: ='Debt Tracker'!L10 -> 2758.32 | E22: ='Debt Tracker'!M10 -> 92 | F22: No | G22: =IF(F22="Yes",D22,0) -> 0 | H22: =H21+G22 -> 0
A23: 7 | B23: ='Debt Tracker'!B11 -> Amex Platinum (Pay Over Time) | C23: ='Debt Tracker'!D11 -> 0.2849 | D23: ='Debt Tracker'!L11 -> 1106.09 | E23: ='Debt Tracker'!M11 -> 40 | F23: No | G23: =IF(F23="Yes",D23,0) -> 0 | H23: =H22+G23 -> 0
A24: 8 | B24: ='Debt Tracker'!B12 -> Affirm — Best Buy (Dec) | C24: ='Debt Tracker'!D12 -> 0.2832 | D24: ='Debt Tracker'!L12 -> 2869.11 | E24: ='Debt Tracker'!M12 -> 151.01 | F24: No | G24: =IF(F24="Yes",D24,0) -> 0 | H24: =H23+G24 -> 0
A25: 9 | B25: ='Debt Tracker'!B14 -> Capital One Quicksilver | C25: ='Debt Tracker'!D14 -> 0.2824 | D25: ='Debt Tracker'!L14 -> 1135.64 | E25: ='Debt Tracker'!M14 -> 38 | F25: No | G25: =IF(F25="Yes",D25,0) -> 0 | H25: =H24+G25 -> 0
A26: 10 | B26: ='Debt Tracker'!B13 -> Affirm — Best Buy (Feb) | C26: ='Debt Tracker'!D13 -> 0.2817 | D26: ='Debt Tracker'!L13 -> 1088.08 | E26: ='Debt Tracker'!M13 -> 72.54 | F26: No | G26: =IF(F26="Yes",D26,0) -> 0 | H26: =H25+G26 -> 0
